Workbook

Sheet Alle Bauteile
A1: Alle Bauteile ProBoter
A3: Teil | B3: Shop / Fertigung | C3: Menge | D3: Einzelpreis inkl. MwSt. (€) | E3: Gesamt inkl. MwSt. (€) | F3: je Probe | G3: Link | H3: Status
A5: Gestell (einmalig)
A6: Gelenkfuß M6x20, Teller 40mm mit Ant-Slip-Platte | B6: DOLD | C6: 4 | D6: 1.83 | E6: =IF(AND(ISNUMBER(C6),ISNUMBER(D6)),C6*D6,0) -> 7.32 | G6: https://www.dold-mechatronik.de/Gelenkfuss-Reihe-10-PA-Gewindestange-mit-Kugel-10mm-M6x20-Schluesselweite-10-Teller-40mm-mit-Anti-Slip-Platte-40-d385 | H6: =IF('zu bestellen'!F14="","",'zu bestellen'!F14) -> identifiziert
A7: Winkel 30 I-Typ inkl. Befestigungssatz | B7: DOLD | C7: 22 | D7: 1.91 | E7: =IF(AND(ISNUMBER(C7),ISNUMBER(D7)),C7*D7,0) -> 42.02 | G7: https://www.dold-mechatronik.de/Winkel-30-I-Typ-Nut-6-inkl-Befestigungssatz-und-Abdeckkappe | H7: =IF('zu bestellen'!F15="","",'zu bestellen'!F15) -> identifiziert
A8: Bügelgriff 100mm mit Befestigungsbohrungen | B8: DOLD | C8: 1 | D8: 8.51 | E8: =IF(AND(ISNUMBER(C8),ISNUMBER(D8)),C8*D8,0) -> 8.51 | G8: https://www.dold-mechatronik.de/Buegelgriff-100mm-mit-Befestigungsbohrungen | H8: =IF('zu bestellen'!F16="","",'zu bestellen'!F16) -> identifiziert
A9: Teleskopschienen Vollauszug 45 kg, 350 mm (1 Paar), DOLD HS-4613-350 | B9: DOLD | C9: 1 | D9: 10.84 | E9: =IF(AND(ISNUMBER(C9),ISNUMBER(D9)),C9*D9,0) -> 10.84 | G9: https://www.dold-mechatronik.de/Vollauszug-45kg-350mm-(1-Paar-Teleskopschienen) | H9: =IF('zu bestellen'!F17="","",'zu bestellen'!F17) -> identifiziert
A10: Aluprofil I-Typ 80x16S Nut 8, 650 mm (Energieketten-Halter) | B10: DOLD | C10: 2 | D10: =0.65*28+0.5 -> 18.7 | E10: =IF(AND(ISNUMBER(C10),ISNUMBER(D10)),C10*D10,0) -> 37.4 | G10: https://www.dold-mechatronik.de/Aluminiumprofil-80x16S-I-Typ-Nut-8-schwer-22kg-m-Zuschnitt-50-6000mm | H10: =IF('zu bestellen'!F18="","",'zu bestellen'!F18) -> identifiziert
A11: Aluprofil I-Typ 30x60x650 | B11: DOLD | C11: 2 | D11: 11.35 | E11: =IF(AND(ISNUMBER(C11),ISNUMBER(D11)),C11*D11,0) -> 22.7 | G11: https://www.dold-mechatronik.de/Aluminiumprofil-30x60L-I-Typ-Nut-6-ZUSCHNITT-bis-1200-mm-1700-EUR-m-030-EUR-pro-Schnitt | H11: =IF('zu bestellen'!F19="","",'zu bestellen'!F19) -> identifiziert
A12: Aluprofil I-Typ 30x30x350 | B12: DOLD | C12: 10 | D12: 3.23 | E12: =IF(AND(ISNUMBER(C12),ISNUMBER(D12)),C12*D12,0) -> 32.3 | G12: https://www.dold-mechatronik.de/Aluminiumprofil-30x30L-I-Typ-Nut-6-ZUSCHNITT-bis-1200-mm-850-EUR-m-025-EUR-pro-Schnitt | H12: =IF('zu bestellen'!F20="","",'zu bestellen'!F20) -> identifiziert
A13: Aluprofil I-Typ 30x30x590 | B13: DOLD | C13: 3 | D13: 5.27 | E13: =IF(AND(ISNUMBER(C13),ISNUMBER(D13)),C13*D13,0) -> 15.81 | G13: https://www.dold-mechatronik.de/Aluminiumprofil-30x30L-I-Typ-Nut-6-ZUSCHNITT-bis-1200-mm-850-EUR-m-025-EUR-pro-Schnitt | H13: =IF('zu bestellen'!F21="","",'zu bestellen'!F21) -> identifiziert
A14: Aluprofil I-Typ 30x30x564 | B14: DOLD | C14: 2 | D14: 5.04 | E14: =IF(AND(ISNUMBER(C14),ISNUMBER(D14)),C14*D14,0) -> 10.08 | G14: https://www.dold-mechatronik.de/Aluminiumprofil-30x30L-I-Typ-Nut-6-ZUSCHNITT-bis-1200-mm-850-EUR-m-025-EUR-pro-Schnitt | H14: =IF('zu bestellen'!F22="","",'zu bestellen'!F22) -> identifiziert
A15: Schubladenplatte | B15: Werkstatt | C15: 1 | D15: 10 | E15: =IF(AND(ISNUMBER(C15),ISNUMBER(D15)),C15*D15,0) -> 10 | G15: siehe Blatt „zu fertigen“ | H15: =IF('zu fertigen'!F56="","",'zu fertigen'!F56) -> identifiziert
A16: Motorplatte, Stahl gelasert, 5mm | B16: Werkstatt | C16: 2 | D16: 80 | E16: =IF(AND(ISNUMBER(C16),ISNUMBER(D16)),C16*D16,0) -> 160 | G16: siehe Blatt „zu fertigen“ | H16: =IF('zu fertigen'!F57="","",'zu fertigen'!F57) -> identifiziert
A17: Profilschienenführung, MR12, 600mm, Edelstahl | B17: DOLD | C17: 2 | D17: 82.2 | E17: =IF(AND(ISNUMBER(C17),ISNUMBER(D17)),C17*D17,0) -> 164.4 | G17: https://www.dold-mechatronik.de/Linearfuehrung-MR-12-M-Edelstahl-600mm | H17: =IF('zu bestellen'!F23="","",'zu bestellen'!F23) -> identifiziert
A18: Übersichtskamera ELP 8MP USB-Kameramodul IMX179, 75° ohne Verzerrung | B18: Amazon | C18: 1 | D18: 63 | E18: =IF(AND(ISNUMBER(C18),ISNUMBER(D18)),C18*D18,0) -> 63 | G18: https://www.amazon.de/dp/B07FXBW81G | H18: =IF('zu bestellen'!F6="","",'zu bestellen'!F6) -> identifiziert
A19: Teller 40 für Gelenkstellfuß Kugel 10 mm, Kunststoff (Ersatz) | B19: DOLD | C19: 1 | D19: 0.53 | E19: =IF(AND(ISNUMBER(C19),ISNUMBER(D19)),C19*D19,0) -> 0.53 | G19: https://www.dold-mechatronik.de/Teller-40-fuer-Gelenkstellfuss-Kugel-10mm-Kunststoff | H19: =IF('zu bestellen'!F24="","",'zu bestellen'!F24) -> identifiziert
A20: Rückwand base_back_plate | B20: Werkstatt | C20: 1 | E20: =IF(AND(ISNUMBER(C20),ISNUMBER(D20)),C20*D20,0) -> 0 | G20: siehe Blatt „zu fertigen“ | H20: =IF('zu fertigen'!F58="","",'zu fertigen'!F58) -> identifiziert
A21: 3D-Druck: base_drag_chain_holder (untere 2 Energieketten-Halter) | B21: 3D-Druck (eigen) | C21: 2 | E21: =IF(AND(ISNUMBER(C21),ISNUMBER(D21)),C21*D21,0) -> 0 | G21: siehe Blatt „zu fertigen“ | H21: =IF('zu fertigen'!F6="","",'zu fertigen'!F6) -> identifiziert
A22: 3D-Druck: base_plate_adapter_1 | B22: 3D-Druck (eigen) | C22: 2 | E22: =IF(AND(ISNUMBER(C22),ISNUMBER(D22)),C22*D22,0) -> 0 | G22: siehe Blatt „zu fertigen“ | H22: =IF('zu fertigen'!F7="","",'zu fertigen'!F7) -> identifiziert
A23: 3D-Druck: base_plate_adapter_2 | B23: 3D-Druck (eigen) | C23: 2 | E23: =IF(AND(ISNUMBER(C23),ISNUMBER(D23)),C23*D23,0) -> 0 | G23: siehe Blatt „zu fertigen“ | H23: =IF('zu fertigen'!F8="","",'zu fertigen'!F8) -> identifiziert
A24: 3D-Druck: base_plate_adapter_left | B24: 3D-Druck (eigen) | C24: 2 | E24: =IF(AND(ISNUMBER(C24),ISNUMBER(D24)),C24*D24,0) -> 0 | G24: siehe Blatt „zu fertigen“ | H24: =IF('zu fertigen'!F9="","",'zu fertigen'!F9) -> identifiziert
A25: 3D-Druck: base_plate_adapter_right | B25: 3D-Druck (eigen) | C25: 2 | E25: =IF(AND(ISNUMBER(C25),ISNUMBER(D25)),C25*D25,0) -> 0 | G25: siehe Blatt „zu fertigen“ | H25: =IF('zu fertigen'!F10="","",'zu fertigen'!F10) -> identifiziert
A26: 3D-Druck: base_cable_holder_m3_flat | B26: 3D-Druck (eigen) | C26: 2 | E26: =IF(AND(ISNUMBER(C26),ISNUMBER(D26)),C26*D26,0) -> 0 | G26: siehe Blatt „zu fertigen“ | H26: =IF('zu fertigen'!F11="","",'zu fertigen'!F11) -> identifiziert
A27: 3D-Druck: base_cable_holder_m4 | B27: 3D-Druck (eigen) | C27: 1 | E27: =IF(AND(ISNUMBER(C27),ISNUMBER(D27)),C27*D27,0) -> 0 | G27: siehe Blatt „zu fertigen“ | H27: =IF('zu fertigen'!F12="","",'zu fertigen'!F12) -> identifiziert
A28: 3D-Druck: base_cable_holder_m5_flat | B28: 3D-Druck (eigen) | C28: 4 | E28: =IF(AND(ISNUMBER(C28),ISNUMBER(D28)),C28*D28,0) -> 0 | G28: siehe Blatt „zu fertigen“ | H28: =IF('zu fertigen'!F13="","",'zu fertigen'!F13) -> identifiziert
A29: 3D-Druck: cable_cover | B29: 3D-Druck (eigen) | C29: 4 | E29: =IF(AND(ISNUMBER(C29),ISNUMBER(D29)),C29*D29,0) -> 0 | G29: siehe Blatt „zu fertigen“ | H29: =IF('zu fertigen'!F14="","",'zu fertigen'!F14) -> identifiziert
A30: 3D-Druck: camera_holder (Übersichtskamera) | B30: 3D-Druck (eigen) | C30: 1 | E30: =IF(AND(ISNUMBER(C30),ISNUMBER(D30)),C30*D30,0) -> 0 | G30: siehe Blatt „zu fertigen“ | H30: =IF('zu fertigen'!F15="","",'zu fertigen'!F15) -> identifiziert
A31: 3D-Druck: camera_holder_top | B31: 3D-Druck (eigen) | C31: 1 | E31: =IF(AND(ISNUMBER(C31),ISNUMBER(D31)),C31*D31,0) -> 0 | G31: siehe Blatt „zu fertigen“ | H31: =IF('zu fertigen'!F16="","",'zu fertigen'!F16) -> identifiziert
A32: 3D-Druck: pcb_holder_glider (PCB-Halter) | B32: 3D-Druck (eigen) | C32: 4 | E32: =IF(AND(ISNUMBER(C32),ISNUMBER(D32)),C32*D32,0) -> 0 | G32: siehe Blatt „zu fertigen“ | H32: =IF('zu fertigen'!F17="","",'zu fertigen'!F17) -> identifiziert
... A35: 3D-Druck: pcb_holder_rod_short_round_d10_mirrored | B35: 3D-Druck (eigen) | C35: 2 | E35: =IF(AND(ISNUMBER(C35),ISNUMBER(D35)),C35*D35,0) -> 0 | G35: siehe Blatt „zu fertigen“ | H35: =IF('zu fertigen'!F20="","",'zu fertigen'!F20) -> identifiziert
A37: X-Antrieb (je Probe)
A38: Schrittmotor NEMA 14 – StepperOnline 14HS13-0804S | B38: StepperOnline | C38: 2 | D38: 7.72 | E38: =IF(AND(ISNUMBER(C38),ISNUMBER(D38)),C38*D38,0) -> 15.44 | F38: x | G38: https://www.omc-stepperonline.com/de/nema-14-bipolar-1-8deg-18ncm-25-5oz-in-0-8a-5-74v-35x35x34mm-4-draehte-14hs13-0804s | H38: =IF('zu bestellen'!F73="","",'zu bestellen'!F73) -> identifiziert
A39: Endschalter induktiv M8, LJ8A3-2-Z/BX (NPN, Schließer, 2 mm) | B39: Amazon | C39: 2 | D39: 6.89 | E39: =IF(AND(ISNUMBER(C39),ISNUMBER(D39)),C39*D39,0) -> 13.78 | F39: x | G39: https://www.amazon.de/Induktive-N%C3%A4herungsschalter-LJ8-A3-2-z-BX-Normalerweise/dp/B072Q68493/ | H39: =IF('zu bestellen'!F7="","",'zu bestellen'!F7) -> identifiziert
A40: 3D-Druck: base_nema_14_to_17_adapter (X-Motor) | B40: 3D-Druck (eigen) | C40: 2 | E40: =IF(AND(ISNUMBER(C40),ISNUMBER(D40)),C40*D40,0) -> 0 | F40: x | G40: siehe Blatt „zu fertigen“ | H40: =IF('zu fertigen'!F21="","",'zu fertigen'!F21) -> identifiziert
A41: 3D-Druck: belt_tightener_GT2_base (X-Riemenspanner) | B41: 3D-Druck (eigen) | C41: 2 | E41: =IF(AND(ISNUMBER(C41),ISNUMBER(D41)),C41*D41,0) -> 0 | F41: x | G41: siehe Blatt „zu fertigen“ | H41: =IF('zu fertigen'!F22="","",'zu fertigen'!F22) -> identifiziert
A42: 3D-Druck: belt_tightener_GT2_wing (X-Riemenspanner) | B42: 3D-Druck (eigen) | C42: 2 | E42: =IF(AND(ISNUMBER(C42),ISNUMBER(D42)),C42*D42,0) -> 0 | F42: x | G42: siehe Blatt „zu fertigen“ | H42: =IF('zu fertigen'!F23="","",'zu fertigen'!F23) -> identifiziert
A44: X-Schlitten inkl. Y-Antrieb / Führung (je Probe)
A45: Linearwagen MR12 MN-SS-V0-N (DOLD) | B45: DOLD | C45: 2 | D45: 41.29 | E45: =IF(AND(ISNUMBER(C45),ISNUMBER(D45)),C45*D45,0) -> 37.2 | F45: x | G45: DOLD-Angebot AN2026-104489, Pos. 19/38 (MR12 MN-SS-V0-N-BLOCK) | H45: =IF('zu bestellen'!F63="","",'zu bestellen'!F63) -> identifiziert
A46: Aluprofil 40x16S I-Typ, 436mm | B46: DOLD | C46: 1 | D46: 4.83 | E46: =IF(AND(ISNUMBER(C46),ISNUMBER(D46)),C46*D46,0) -> 4.83 | F46: x | G46: https://www.dold-mechatronik.de/Aluminiumprofil-40x16S-I-Typ-Nut-8-ZUSCHNITT-bis-1200-mm-1050-EUR-m-025-EUR-pro-Schnitt | H46: =IF('zu bestellen'!F25="","",'zu bestellen'!F25) -> identifiziert
...

Sheet zu bestellen
A1: zu bestellen – nach Shop (Mengen für Vollausbau, 4 Proben)
A3: Teil | B3: Menge Vollausbau | C3: Einzelpreis inkl. MwSt. (€) | D3: Gesamt inkl. MwSt. (€) | E3: Link | F3: Status
A5: Amazon
A6: ='Alle Bauteile'!A18 -> Übersichtskamera ELP 8MP USB-Kameramodul IMX179, 75° ohne Verzerrung | B6: =IF('Alle Bauteile'!C18="","",IF('Alle Bauteile'!F18="x",4*'Alle Bauteile'!C18,'Alle Bauteile'!C18)) -> 1 | C6: =IF('Alle Bauteile'!D18="","",'Alle Bauteile'!D18) -> 63 | D6: =IF(AND(ISNUMBER(B6),ISNUMBER(C6)),B6*C6,0) -> 63 | E6: =IF('Alle Bauteile'!G18="","",'Alle Bauteile'!G18) -> https://www.amazon.de/dp/B07FXBW81G | F6: identifiziert
A7: ='Alle Bauteile'!A39 -> Endschalter induktiv M8, LJ8A3-2-Z/BX (NPN, Schließer, 2 mm) | B7: =IF('Alle Bauteile'!C39="","",IF('Alle Bauteile'!F39="x",4*'Alle Bauteile'!C39,'Alle Bauteile'!C39)) -> 8 | C7: =IF('Alle Bauteile'!D39="","",'Alle Bauteile'!D39) -> 6.89 | D7: =IF(AND(ISNUMBER(B7),ISNUMBER(C7)),B7*C7,0) -> 55.12 | E7: =IF('Alle Bauteile'!G39="","",'Alle Bauteile'!G39) -> https://www.amazon.de/Induktive-N%C3%A4herungsschalter-LJ8-A3-2-z-BX-Normalerweise/dp/B072Q68493/ | F7: identifiziert
A8: ='Alle Bauteile'!A51 -> Endschalter induktiv M8, LJ8A3-2-Z/BX (NPN, Schließer, 2 mm) | B8: =IF('Alle Bauteile'!C51="","",IF('Alle Bauteile'!F51="x",4*'Alle Bauteile'!C51,'Alle Bauteile'!C51)) -> 4 | C8: =IF('Alle Bauteile'!D51="","",'Alle Bauteile'!D51) -> 6.89 | D8: =IF(AND(ISNUMBER(B8),ISNUMBER(C8)),B8*C8,0) -> 27.56 | E8: =IF('Alle Bauteile'!G51="","",'Alle Bauteile'!G51) -> https://www.amazon.de/Induktive-N%C3%A4herungsschalter-LJ8-A3-2-z-BX-Normalerweise/dp/B072Q68493/ | F8: identifiziert
A9: ='Alle Bauteile'!A71 -> 6 Stück optische Endstops mit Kabel | B9: =IF('Alle Bauteile'!C71="","",IF('Alle Bauteile'!F71="x",4*'Alle Bauteile'!C71,'Alle Bauteile'!C71)) -> 4 | C9: =IF('Alle Bauteile'!D71="","",'Alle Bauteile'!D71) -> 10.69 | D9: =IF(AND(ISNUMBER(B9),ISNUMBER(C9)),B9*C9,0) -> 42.76 | E9: =IF('Alle Bauteile'!G71="","",'Alle Bauteile'!G71) -> https://www.amazon.de/gp/product/B07PX8ZFXN/ref=ox_sc_act_title_2?smid=AS8JK4HNTE2NO&psc=1 | F9: identifiziert
A10: ='Alle Bauteile'!A99 -> USB-Hub | B10: =IF('Alle Bauteile'!C99="","",IF('Alle Bauteile'!F99="x",4*'Alle Bauteile'!C99,'Alle Bauteile'!C99)) -> 1 | C10: =IF('Alle Bauteile'!D99="","",'Alle Bauteile'!D99) -> 9.99 | D10: =IF(AND(ISNUMBER(B10),ISNUMBER(C10)),B10*C10,0) -> 9.99 | E10: =IF('Alle Bauteile'!G99="","",'Alle Bauteile'!G99) -> https://www.amazon.de/Anker-Datenhub-Ultrabooks-weiteren-kompatiblen/dp/B00Y211AFM/ | F10: identifiziert
A11: Summe Amazon | D11: =SUM(D6:D10) -> 198.43
A13: DOLD
A14: ='Alle Bauteile'!A6 -> Gelenkfuß M6x20, Teller 40mm mit Ant-Slip-Platte | B14: =IF('Alle Bauteile'!C6="","",IF('Alle Bauteile'!F6="x",4*'Alle Bauteile'!C6,'Alle Bauteile'!C6)) -> 4 | C14: =IF('Alle Bauteile'!D6="","",'Alle Bauteile'!D6) -> 1.83 | D14: =IF(AND(ISNUMBER(B14),ISNUMBER(C14)),B14*C14,0) -> 7.32 | E14: =IF('Alle Bauteile'!G6="","",'Alle Bauteile'!G6) -> https://www.dold-mechatronik.de/Gelenkfuss-Reihe-10-PA-Gewindestange-mit-Kugel-10mm-M6x20-Schluesselweite-10-Teller-40mm-mit-Anti-Slip-Platte-40-d385 | F14: identifiziert
A15: ='Alle Bauteile'!A7 -> Winkel 30 I-Typ inkl. Befestigungssatz | B15: =IF('Alle Bauteile'!C7="","",IF('Alle Bauteile'!F7="x",4*'Alle Bauteile'!C7,'Alle Bauteile'!C7)) -> 22 | C15: =IF('Alle Bauteile'!D7="","",'Alle Bauteile'!D7) -> 1.91 | D15: =IF(AND(ISNUMBER(B15),ISNUMBER(C15)),B15*C15,0) -> 42.02 | E15: =IF('Alle Bauteile'!G7="","",'Alle Bauteile'!G7) -> https://www.dold-mechatronik.de/Winkel-30-I-Typ-Nut-6-inkl-Befestigungssatz-und-Abdeckkappe | F15: identifiziert
A16: ='Alle Bauteile'!A8 -> Bügelgriff 100mm mit Befestigungsbohrungen | B16: =IF('Alle Bauteile'!C8="","",IF('Alle Bauteile'!F8="x",4*'Alle Bauteile'!C8,'Alle Bauteile'!C8)) -> 1 | C16: =IF('Alle Bauteile'!D8="","",'Alle Bauteile'!D8) -> 8.51 | D16: =IF(AND(ISNUMBER(B16),ISNUMBER(C16)),B16*C16,0) -> 8.51 | E16: =IF('Alle Bauteile'!G8="","",'Alle Bauteile'!G8) -> https://www.dold-mechatronik.de/Buegelgriff-100mm-mit-Befestigungsbohrungen | F16: identifiziert
A17: ='Alle Bauteile'!A9 -> Teleskopschienen Vollauszug 45 kg, 350 mm (1 Paar), DOLD HS-4613-350 | B17: =IF('Alle Bauteile'!C9="","",IF('Alle Bauteile'!F9="x",4*'Alle Bauteile'!C9,'Alle Bauteile'!C9)) -> 1 | C17: =IF('Alle Bauteile'!D9="","",'Alle Bauteile'!D9) -> 10.84 | D17: =IF(AND(ISNUMBER(B17),ISNUMBER(C17)),B17*C17,0) -> 10.84 | E17: =IF('Alle Bauteile'!G9="","",'Alle Bauteile'!G9) -> https://www.dold-mechatronik.de/Vollauszug-45kg-350mm-(1-Paar-Teleskopschienen) | F17: identifiziert
A18: ='Alle Bauteile'!A10 -> Aluprofil I-Typ 80x16S Nut 8, 650 mm (Energieketten-Halter) | B18: =IF('Alle Bauteile'!C10="","",IF('Alle Bauteile'!F10="x",4*'Alle Bauteile'!C10,'Alle Bauteile'!C10)) -> 2 | C18: =IF('Alle Bauteile'!D10="","",'Alle Bauteile'!D10) -> 18.7 | D18: =IF(AND(ISNUMBER(B18),ISNUMBER(C18)),B18*C18,0) -> 37.4 | E18: =IF('Alle Bauteile'!G10="","",'Alle Bauteile'!G10) -> https://www.dold-mechatronik.de/Aluminiumprofil-80x16S-I-Typ-Nut-8-schwer-22kg-m-Zuschnitt-50-6000mm | F18: identifiziert
A19: ='Alle Bauteile'!A11 -> Aluprofil I-Typ 30x60x650 | B19: =IF('Alle Bauteile'!C11="","",IF('Alle Bauteile'!F11="x",4*'Alle Bauteile'!C11,'Alle Bauteile'!C11)) -> 2 | C19: =IF('Alle Bauteile'!D11="","",'Alle Bauteile'!D11) -> 11.35 | D19: =IF(AND(ISNUMBER(B19),ISNUMBER(C19)),B19*C19,0) -> 22.7 | E19: =IF('Alle Bauteile'!G11="","",'Alle Bauteile'!G11) -> https://www.dold-mechatronik.de/Aluminiumprofil-30x60L-I-Typ-Nut-6-ZUSCHNITT-bis-1200-mm-1700-EUR-m-030-EUR-pro-Schnitt | F19: identifiziert
A20: ='Alle Bauteile'!A12 -> Aluprofil I-Typ 30x30x350 | B20: =IF('Alle Bauteile'!C12="","",IF('Alle Bauteile'!F12="x",4*'Alle Bauteile'!C12,'Alle Bauteile'!C12)) -> 10 | C20: =IF('Alle Bauteile'!D12="","",'Alle Bauteile'!D12) -> 3.23 | D20: =IF(AND(ISNUMBER(B20),ISNUMBER(C20)),B20*C20,0) -> 32.3 | E20: =IF('Alle Bauteile'!G12="","",'Alle Bauteile'!G12) -> https://www.dold-mechatronik.de/Aluminiumprofil-30x30L-I-Typ-Nut-6-ZUSCHNITT-bis-1200-mm-850-EUR-m-025-EUR-pro-Schnitt | F20: identifiziert
A21: ='Alle Bauteile'!A13 -> Aluprofil I-Typ 30x30x590 | B21: =IF('Alle Bauteile'!C13="","",IF('Alle Bauteile'!F13="x",4*'Alle Bauteile'!C13,'Alle Bauteile'!C13)) -> 3 | C21: =IF('Alle Bauteile'!D13="","",'Alle Bauteile'!D13) -> 5.27 | D21: =IF(AND(ISNUMBER(B21),ISNUMBER(C21)),B21*C21,0) -> 15.81 | E21: =IF('Alle Bauteile'!G13="","",'Alle Bauteile'!G13) -> https://www.dold-mechatronik.de/Aluminiumprofil-30x30L-I-Typ-Nut-6-ZUSCHNITT-bis-1200-mm-850-EUR-m-025-EUR-pro-Schnitt | F21: identifiziert
A22: ='Alle Bauteile'!A14 -> Aluprofil I-Typ 30x30x564 | B22: =IF('Alle Bauteile'!C14="","",IF('Alle Bauteile'!F14="x",4*'Alle Bauteile'!C14,'Alle Bauteile'!C14)) -> 2 | C22: =IF('Alle Bauteile'!D14="","",'Alle Bauteile'!D14) -> 5.04 | D22: =IF(AND(ISNUMBER(B22),ISNUMBER(C22)),B22*C22,0) -> 10.08 | E22: =IF('Alle Bauteile'!G14="","",'Alle Bauteile'!G14) -> https://www.dold-mechatronik.de/Aluminiumprofil-30x30L-I-Typ-Nut-6-ZUSCHNITT-bis-1200-mm-850-EUR-m-025-EUR-pro-Schnitt | F22: identifiziert
A23: ='Alle Bauteile'!A17 -> Profilschienenführung, MR12, 600mm, Edelstahl | B23: =IF('Alle Bauteile'!C17="","",IF('Alle Bauteile'!F17="x",4*'Alle Bauteile'!C17,'Alle Bauteile'!C17)) -> 2 | C23: =IF('Alle Bauteile'!D17="","",'Alle Bauteile'!D17) -> 82.2 | D23: =IF(AND(ISNUMBER(B23),ISNUMBER(C23)),B23*C23,0) -> 164.4 | E23: =IF('Alle Bauteile'!G17="","",'Alle Bauteile'!G17) -> https://www.dold-mechatronik.de/Linearfuehrung-MR-12-M-Edelstahl-600mm | F23: identifiziert
A24: ='Alle Bauteile'!A19 -> Teller 40 für Gelenkstellfuß Kugel 10 mm, Kunststoff (Ersatz) | B24: =IF('Alle Bauteile'!C19="","",IF('Alle Bauteile'!F19="x",4*'Alle Bauteile'!C19,'Alle Bauteile'!C19)) -> 1 | C24: =IF('Alle Bauteile'!D19="","",'Alle Bauteile'!D19) -> 0.53 | D24: =IF(AND(ISNUMBER(B24),ISNUMBER(C24)),B24*C24,0) -> 0.53 | E24: =IF('Alle Bauteile'!G19="","",'Alle Bauteile'!G19) -> https://www.dold-mechatronik.de/Teller-40-fuer-Gelenkstellfuss-Kugel-10mm-Kunststoff | F24: identifiziert
A25: ='Alle Bauteile'!A46 -> Aluprofil 40x16S I-Typ, 436mm | B25: =IF('Alle Bauteile'!C46="","",IF('Alle Bauteile'!F46="x",4*'Alle Bauteile'!C46,'Alle Bauteile'!C46)) -> 4 | C25: =IF('Alle Bauteile'!D46="","",'Alle Bauteile'!D46) -> 4.83 | D25: =IF(AND(ISNUMBER(B25),ISNUMBER(C25)),B25*C25,0) -> 19.32 | E25: =IF('Alle Bauteile'!G46="","",'Alle Bauteile'!G46) -> https://www.dold-mechatronik.de/Aluminiumprofil-40x16S-I-Typ-Nut-8-ZUSCHNITT-bis-1200-mm-1050-EUR-m-025-EUR-pro-Schnitt | F25: identifiziert
A26: ='Alle Bauteile'!A49 -> Wellenhalter Flansch SHF10, D10 | B26: =IF('Alle Bauteile'!C49="","",IF('Alle Bauteile'!F49="x",4*'Alle Bauteile'!C49,'Alle Bauteile'!C49)) -> 16 | C26: =IF('Alle Bauteile'!D49="","",'Alle Bauteile'!D49) -> 3.8 | D26: =IF(AND(ISNUMBER(B26),ISNUMBER(C26)),B26*C26,0) -> 60.8 | E26: =IF('Alle Bauteile'!G49="","",'Alle Bauteile'!G49) -> https://www.dold-mechatronik.de/Wellenhalter-Flansch-SHF-Ausfuehrung-waehlbar | F26: identifiziert
A27: ='Alle Bauteile'!A50 -> Präzisionswelle D10, 450mm mit M6 Gewinde | B27: =IF('Alle Bauteile'!C50="","",IF('Alle Bauteile'!F50="x",4*'Alle Bauteile'!C50,'Alle Bauteile'!C50)) -> 8 | C27: =IF('Alle Bauteile'!D50="","",'Alle Bauteile'!D50) -> 8.7 | D27: =IF(AND(ISNUMBER(B27),ISNUMBER(C27)),B27*C27,0) -> 69.6 | E27: =IF('Alle Bauteile'!G50="","",'Alle Bauteile'!G50) -> https://www.dold-mechatronik.de/Praezisionswelle-10mm-h6-geschliffen-gehaertet-450mm-mit-Gewindebohrungen-M5x20 | F27: identifiziert
A28: ='Alle Bauteile'!A64 -> Vollkunststoffgleitlager RJMP DryLin igus, D10 | B28: =IF('Alle Bauteile'!C64="","",IF('Alle Bauteile'!F64="x",4*'Alle Bauteile'!C64,'Alle Bauteile'!C64)) -> 16 | C28: =IF('Alle Bauteile'!D64="","",'Alle Bauteile'!D64) -> 4.2 | D28: =IF(AND(ISNUMBER(B28),ISNUMBER(C28)),B28*C28,0) -> 67.2 | E28: =IF('Alle Bauteile'!G64="","",'Alle Bauteile'!G64) -> https://www.dold-mechatronik.de/Vollkunststofflager-RJMP-01-10-DryLinZ-von-igusZ | F28: identifiziert
A29: ='Alle Bauteile'!A65 -> Sicherungsring Bohrung DIN 472, D22 | B29: =IF('Alle Bauteile'!C65="","",IF('Alle Bauteile'!F65="x",4*'Alle Bauteile'!C65,'Alle Bauteile'!C65)) -> 16 | C29: =IF('Alle Bauteile'!D65="","",'Alle Bauteile'!D65) -> 0.15 | D29: =IF(AND(ISNUMBER(B29),ISNUMBER(C29)),B29*C29,0) -> 2.4 | E29: =IF('Alle Bauteile'!G65="","",'Alle Bauteile'!G65) -> https://www.dold-mechatronik.de/DIN-472-Form-I-Sicherungsring-fuer-Bohrungen-Stahl-blank-I22 | F29: identifiziert
A30: ='Alle Bauteile'!A67 -> Zahnriemenrad GT2 6mm, 16 Zähne, Bohrung 5 mm (X, Y, Z) | B30: =IF('Alle Bauteile'!C67="","",IF('Alle Bauteile'!F67="x",4*'Alle Bauteile'!C67,'Alle Bauteile'!C67)) -> 16 | C30: =IF('Alle Bauteile'!D67="","",'Alle Bauteile'!D67) -> 2.9 | D30: =IF(AND(ISNUMBER(B30),ISNUMBER(C30)),B30*C30,0) -> 46.4 | E30: =IF('Alle Bauteile'!G67="","",'Alle Bauteile'!G67) -> https://www.dold-mechatronik.de/Zahnriemenrad-GT2-6mm-breit-16-Zaehne-Bohrung-500mm-H7-mit-Klemmschrauben | F30: identifiziert
A31: ='Alle Bauteile'!A68 -> Umlenkrolle GT2 6mm, 16 Zähne, mit Kugellager, Bohrung 3 mm (X, Y, Z) | B31: =IF('Alle Bauteile'!C68="","",IF('Alle Bauteile'!F68="x",4*'Alle Bauteile'!C68,'Alle Bauteile'!C68)) -> 16 | C31: =IF('Alle Bauteile'!D68="","",'Alle Bauteile'!D68) -> 3.2 | D31: =IF(AND(ISNUMBER(B31),ISNUMBER(C31)),B31*C31,0) -> 51.2 | E31: =IF('Alle Bauteile'!G68="","",'Alle Bauteile'!G68) -> https://www.dold-mechatronik.de/Umlenkrolle-Zahnriemenrad-mit-Kugellager-GT2-6mm-breit-16-Zaehne-Bohrung-300mm | F31: identifiziert
A32: ='Alle Bauteile'!A69 -> Zahnriemen GT2, 6 mm breit, je 1 Meter (X, Y, Z) | B32: =IF('Alle Bauteile'!C69="","",IF('Alle Bauteile'!F69="x",4*'Alle Bauteile'!C69,'Alle Bauteile'!C69)) -> 20 | C32: =IF('Alle Bauteile'!D69="","",'Alle Bauteile'!D69) -> 2.5 | D32: =IF(AND(ISNUMBER(B32),ISNUMBER(C32)),B32*C32,0) -> 50 | E32: =IF('Alle Bauteile'!G69="","",'Alle Bauteile'!G69) -> https://www.dold-mechatronik.de/Zahnriemen-GT2-Breite-6mm-Laenge-1-Meter | F32: identifiziert
A33: ='Alle Bauteile'!A81 -> Profilschienenführung, MR12, 150mm, Edelstahl | B33: =IF('Alle Bauteile'!C81="","",IF('Alle Bauteile'!F81="x",4*'Alle Bauteile'!C81,'Alle Bauteile'!C81)) -> 4 | C33: =IF('Alle Bauteile'!D81="","",'Alle Bauteile'!D81) -> 20.55 | D33: =IF(AND(ISNUMBER(B33),ISNUMBER(C33)),B33*C33,0) -> 82.2 | E33: =IF('Alle Bauteile'!G81="","",'Alle Bauteile'!G81) -> https://www.dold-mechatronik.de/Linearfuehrung-MR-12-M-Edelstahl-150mm | F33: identifiziert
A34: ='Alle Bauteile'!A91 -> Schaltnetzteil Mean Well SDR-240-24, Hutschiene, 24 V / 10 A / 240 W | B34: =IF('Alle Bauteile'!C91="","",IF('Alle Bauteile'!F91="x",4*'Alle Bauteile'!C91,'Alle Bauteile'!C91)) -> 1 | C34: =IF('Alle Bauteile'!D91="","",'Alle Bauteile'!D91) -> 84.79 | D34: =IF(AND(ISNUMBER(B34),ISNUMBER(C34)),B34*C34,0) -> 84.79 | E34: =IF('Alle Bauteile'!G91="","",'Alle Bauteile'!G91) -> https://www.dold-mechatronik.de/Switching-power-supply-DIN-rail-240-W-24-V-10-A | F34: identifiziert
A35: ='Alle Bauteile'!A116 -> DIN 912 (ISO 4762) Zylinderschraube M3x8, A2 | B35: =IF('Alle Bauteile'!C116="","",IF('Alle Bauteile'!F116="x",4*'Alle Bauteile'!C116,'Alle Bauteile'!C116)) -> 58 | C35: =IF('Alle Bauteile'!D116="","",'Alle Bauteile'!D116) | D35: =IF(AND(ISNUMBER(B35),ISNUMBER(C35)),B35*C35,0) -> 0 | E35: =IF('Alle Bauteile'!G116="","",'Alle Bauteile'!G116) -> https://www.dold-mechatronik.de/DIN-912-Zylinderschraube-mit-Innensechskant,-Edelstahl-A2 | F35: identifiziert
A36: ='Alle Bauteile'!A117 -> DIN 912 (ISO 4762) Zylinderschraube M3x10, A2 | B36: =IF('Alle Bauteile'!C117="","",IF('Alle Bauteile'!F117="x",4*'Alle Bauteile'!C117,'Alle Bauteile'!C117)) -> 66 | C36: =IF('Alle Bauteile'!D117="","",'Alle Bauteile'!D117) | D36: =IF(AND(ISNUMBER(B36),ISNUMBER(C36)),B36*C36,0) -> 0 | E36: =IF('Alle Bauteile'!G117="","",'Alle Bauteile'!G117) -> https://www.dold-mechatronik.de/DIN-912-Zylinderschraube-mit-Innensechskant,-Edelstahl-A2 | F36: identifiziert
A37: ='Alle Bauteile'!A118 -> DIN 912 (ISO 4762) Zylinderschraube M3x12, A2 | B37: =IF('Alle Bauteile'!C118="","",IF('Alle Bauteile'!F118="x",4*'Alle Bauteile'!C118,'Alle Bauteile'!C118)) -> 10 | C37: =IF('Alle Bauteile'!D118="","",'Alle Bauteile'!D118) | D37: =IF(AND(ISNUMBER(B37),ISNUMBER(C37)),B37*C37,0) -> 0 | E37: =IF('Alle Bauteile'!G118="","",'Alle Bauteile'!G118) -> https://www.dold-mechatronik.de/DIN-912-Zylinderschraube-mit-Innensechskant,-Edelstahl-A2 | F37: identifiziert
A38: ='Alle Bauteile'!A119 -> DIN 912 (ISO 4762) Zylinderschraube M3x14, A2 | B38: =IF('Alle Bauteile'!C119="","",IF('Alle Bauteile'!F119="x",4*'Alle Bauteile'!C119,'Alle Bauteile'!C119)) -> 6 | C38: =IF('Alle Bauteile'!D119="","",'Alle Bauteile'!D119) | D38: =IF(AND(ISNUMBER(B38),ISNUMBER(C38)),B38*C38,0) -> 0 | E38: =IF('Alle Bauteile'!G119="","",'Alle Bauteile'!G119) -> https://www.dold-mechatronik.de/DIN-912-Zylinderschraube-mit-Innensechskant,-Edelstahl-A2 | F38: identifiziert
A39: ='Alle Bauteile'!A120 -> DIN 912 (ISO 4762) Zylinderschraube M3x16, A2 | B39: =IF('Alle Bauteile'!C120="","",IF('Alle Bauteile'!F120="x",4*'Alle Bauteile'!C120,'Alle Bauteile'!C120)) -> 22 | C39: =IF('Alle Bauteile'!D120="","",'Alle Bauteile'!D120) | D39: =IF(AND(ISNUMBER(B39),ISNUMBER(C39)),B39*C39,0) -> 0 | E39: =IF('Alle Bauteile'!G120="","",'Alle Bauteile'!G120) -> https://www.dold-mechatronik.de/DIN-912-Zylinderschraube-mit-Innensechskant,-Edelstahl-A2 | F39: identifiziert
A40: ='Alle Bauteile'!A121 -> DIN 912 (ISO 4762) Zylinderschraube M3x18, A2 | B40: =IF('Alle Bauteile'!C121="","",IF('Alle Bauteile'!F121="x",4*'Alle Bauteile'!C121,'Alle Bauteile'!C121)) -> 36 | C40: =IF('Alle Bauteile'!D121="","",'Alle Bauteile'!D121) | D40: =IF(AND(ISNUMBER(B40),ISNUMBER(C40)),B40*C40,0) -> 0 | E40: =IF('Alle Bauteile'!G121="","",'Alle Bauteile'!G121) -> https://www.dold-mechatronik.de/DIN-912-Zylinderschraube-mit-Innensechskant,-Edelstahl-A2 | F40: identifiziert
A41: ='Alle Bauteile'!A122 -> DIN 912 (ISO 4762) Zylinderschraube M3x20, A2 | B41: =IF('Alle Bauteile'!C122="","",IF('Alle Bauteile'!F122="x",4*'Alle Bauteile'!C122,'Alle Bauteile'!C122)) -> 6 | C41: =IF('Alle Bauteile'!D122="","",'Alle Bauteile'!D122) | D41: =IF(AND(ISNUMBER(B41),ISNUMBER(C41)),B41*C41,0) -> 0 | E41: =IF('Alle Bauteile'!G122="","",'Alle Bauteile'!G122) -> https://www.dold-mechatronik.de/DIN-912-Zylinderschraube-mit-Innensechskant,-Edelstahl-A2 | F41: identifiziert
A42: ='Alle Bauteile'!A123 -> DIN 912 (ISO 4762) Zylinderschraube M3x30, A2 | B42: =IF('Alle Bauteile'!C123="","",IF('Alle Bauteile'!F123="x",4*'Alle Bauteile'!C123,'Alle Bauteile'!C123)) -> 10 | C42: =IF('Alle Bauteile'!D123="","",'Alle Bauteile'!D123) | D42: =IF(AND(ISNUMBER(B42),ISNUMBER(C42)),B42*C42,0) -> 0 | E42: =IF('Alle Bauteile'!G123="","",'Alle Bauteile'!G123) -> https://www.dold-mechatronik.de/DIN-912-Zylinderschraube-mit-Innensechskant,-Edelstahl-A2 | F42: identifiziert
A43: ='Alle Bauteile'!A124 -> DIN 912 (ISO 4762) Zylinderschraube M4x10, A2 | B43: =IF('Alle Bauteile'!C124="","",IF('Alle Bauteile'!F124="x",4*'Alle Bauteile'!C124,'Alle Bauteile'!C124)) -> 3 | C43: =IF('Alle Bauteile'!D124="","",'Alle Bauteile'!D124) | D43: =IF(AND(ISNUMBER(B43),ISNUMBER(C43)),B43*C43,0) -> 0 | E43: =IF('Alle Bauteile'!G124="","",'Alle Bauteile'!G124) -> https://www.dold-mechatronik.de/DIN-912-Zylinderschraube-mit-Innensechskant,-Edelstahl-A2 | F43: identifiziert
...

Sheet zu fertigen
A1: zu fertigen – 3D-Druck, Werkstatt, Leiterplatten (Mengen für Vollausbau, 4 Proben)
A3: Teil | B3: Fertigung | C3: Anzahl | D3: Material | E3: Einbauort | F3: Status
A5: 3D-Druck
A6: base_drag_chain_holder (untere 2 Energieketten-Halter) | B6: 3D-Druck | C6: 2 | D6: PETG | E6: Gestell | F6: identifiziert
A7: base_plate_adapter_1 | B7: 3D-Druck | C7: 2 | D7: PETG | E7: Gestell | F7: identifiziert
A8: base_plate_adapter_2 | B8: 3D-Druck | C8: 2 | D8: PETG | E8: Gestell | F8: identifiziert
A9: base_plate_adapter_left | B9: 3D-Druck | C9: 2 | D9: PETG | E9: Gestell | F9: identifiziert
A10: base_plate_adapter_right | B10: 3D-Druck | C10: 2 | D10: PETG | E10: Gestell | F10: identifiziert
A11: base_cable_holder_m3_flat | B11: 3D-Druck | C11: 2 | D11: PETG | E11: Gestell | F11: identifiziert
A12: base_cable_holder_m4 | B12: 3D-Druck | C12: 1 | D12: PETG | E12: Gestell | F12: identifiziert
A13: base_cable_holder_m5_flat | B13: 3D-Druck | C13: 4 | D13: PETG | E13: Gestell | F13: identifiziert
A14: cable_cover | B14: 3D-Druck | C14: 4 | D14: PETG | E14: Gestell | F14: identifiziert
A15: camera_holder (Übersichtskamera) | B15: 3D-Druck | C15: 1 | D15: PETG | E15: Gestell | F15: identifiziert
A16: camera_holder_top | B16: 3D-Druck | C16: 1 | D16: PETG | E16: Gestell | F16: identifiziert
A17: pcb_holder_glider (PCB-Halter) | B17: 3D-Druck | C17: 4 | D17: PETG | E17: Gestell | F17: identifiziert
... A53: utils_height_leveling_probe_holder | B53: 3D-Druck | C53: 1 | D53: PETG | E53: Hilfsmittel | F53: identifiziert
A55: Werkstatt
A56: Schubladenplatte | B56: Werkstatt | C56: 1 | E56: Gestell | F56: identifiziert
A57: Motorplatte, Stahl gelasert, 5mm | B57: Werkstatt | C57: 2 | D57: Stahl, 5 mm | E57: Gestell | F57: identifiziert
A58: Rückwand base_back_plate | B58: Werkstatt | C58: 1 | E58: Gestell | F58: identifiziert
A59: Seitenplatten, Stahl, gelasert, 5mm | B59: Werkstatt | C59: 8 | D59: Stahl, 5 mm | E59: X-Schlitten inkl. Y-Antrieb / Führung | F59: identifiziert
A60: Bearbeitung: Aluprofil 80x16S Energieketten-Halter, 20 × M3-Gewinde je Profil | B60: Werkstatt | C60: 2 | D60: Alu (DOLD 60886-Z, gekauft) | E60: Gestell | F60: identifiziert
A61: Bearbeitung: x_slide_stiffener_beam (Aluprofil 40x16S, 436 mm) nach Zeichnung | B61: Werkstatt | C61: 4 | D61: Alu (DOLD 60879-Z, gekauft) | E61: X-Schlitten | F61: identifiziert
A63: Leiterplatten (JLCPCB)
A64: Multiplexerboard (signal-multiplexer, Gerber 1.1) | B64: Leiterplatten (JLCPCB) | C64: 1 | D64: FR4, bestückt | E64: Elektronik | F64: identifiziert
A65: Probing-Board (probe_tip_pcb) | B65: Leiterplatten (JLCPCB) | C65: 4 | D65: FR4 | E65: Elektronik | F65: identifiziert
A68: Orange = Anzahl oder Material fehlt noch. Status: identifiziert → in Fertigung → gefertigt → verbaut.
